Workbook

Sheet داشبورد مانیتورینگ نواحی
A1: سامانه هوشمند مانیتورینگ و ارزیابی جامع عملکرد نواحی و کارمندان نسرا - استان اصفهان
A2: ="سال ارزیابی: " & 'کارنامه هوشمند'!E3 & " | دوره ارزیابی: ماه " & 'کارنامه هوشمند'!C3 & " | مبنای سنجش: شاخص‌های ابلاغی به ازای هر حوزه مقاومت | پایش برخط و خودکار متصل به گزارش عملکرد ماهانه" | V2: 📸 خروجی تصویر داشبورد
B4: 🏢 پوشش تشکیلاتی استان | E4: 📊 میانگین نمره عملکرد استان | I4: 🏆 پیشتاز عملکرد استان (رتبه ۱) | M4: 📥 وضعیت دریافت گزارش ماهانه | Q4: 🎯 تفکیک سطوح کیفی عملکرد نواحی
B5: ۳۲ ناحیه | ۲۲۹ حوزه مقاومت | E5: =IFERROR(AVERAGE(T31:T62), 0) | I5: =IF(MAX(T31:T62)>0, INDEX(B31:B62, MATCH(MAX(T31:T62), T31:T62, 0)), "در انتظار ثبت داده") | M5: =COUNTIF(W31:W62, "ثبت شده") & " از ۳۲ ناحیه" | Q5: ="عالی: " & COUNTIF(V31:V62, "عالی*") & " | خوب: " & COUNTIF(V31:V62, "خوب*") & " | متوسط: " & COUNTIF(V31:V62, "متوسط*") & " | ضعیف: " & COUNTIF(V31:V62, "ضعیف*")
B6: ="مجموع مدرسان هدف: " & TEXT(SUM('پایگاه داده حد انتظار'!$H$2:$H$33),"#,##0") & " نفر" | E6: =IF(E5>=1,"تحقق ۱۰۰٪ اهداف استانی",IF(E5>=0.75,"عملکرد بسیار مطلوب",IF(E5>=0.5,"عملکرد متوسط","نیازمند مداخله و پیگیری"))) | I6: =IF(MAX(T31:T62)>0, "نمره تحقق: " & TEXT(MAX(T31:T62), "0.0%"), "-") | M6: ="نرخ مشارکت: " & TEXT(COUNTIF(W31:W62, "ثبت شده")/32, "0.0%") | Q6: ="نواحی فاقد گزارش: " & COUNTIF(W31:W62, "فاقد گزارش") & " ناحیه"
B9: ۱. ارزیابی و پایش تحقق شاخص‌های کلان در سطح کل استان اصفهان (تجمیعی)
B10: عنوان شاخص عملکردی | C10: مبنای ابلاغی | D10: حد انتظار کل استان | E10: عملکرد کل استان | F10: انحراف از هدف | G10: درصد تحقق استان | H10: میانگین تحقق نواحی | I10: وضعیت استانی | J10: مرجع در گزارش ماهانه | K10: توضیحات و اجزا
B11: سواد رسانه حضوری و توانمندسازی | C11: ۳۱× به ازای هر حوزه | D11: =SUM('پایگاه داده حد انتظار'!$C$2:$C$33) | E11: =SUM('گزارش عملکرد ماهانه'!$B$2:$B$33) | F11: =E11-D11 | G11: =IFERROR(E11/D11, 0) | H11: =AVERAGE(F31:F62) | I11: =IF(G11>=1, "تحقق کامل", IF(G11>=0.75, "مطلوب", IF(G11>=0.5, "متوسط", "نیازمند جهش"))) | J11: شیت حضوری + توانمندسازی | K11: مجموع کارگاه‌ها و نشست‌های حضوری
B12: سواد رسانه مجازی و لایو | C12: ۲۱۷× به ازای هر حوزه | D12: =SUM('پایگاه داده حد انتظار'!$D$2:$D$33) | E12: =SUM('گزارش عملکرد ماهانه'!$C$2:$C$33) | F12: =E12-D12 | G12: =IFERROR(E12/D12, 0) | H12: =AVERAGE(I31:I62) | I12: =IF(G12>=1, "تحقق کامل", IF(G12>=0.75, "مطلوب", IF(G12>=0.5, "متوسط", "نیازمند جهش"))) | J12: شیت سوادرسانه مجازی | K12: پخش زنده، وبینار و آموزش مجازی
B13: اقدامات و ابتکارات خلاقانه | C13: ۶۲× به ازای هر حوزه | D13: =SUM('پایگاه داده حد انتظار'!$E$2:$E$33) | E13: =SUM('گزارش عملکرد ماهانه'!$D$2:$D$33) | F13: =E13-D13 | G13: =IFERROR(E13/D13, 0) | H13: =AVERAGE(L31:L62) | I13: =IF(G13>=1, "تحقق کامل", IF(G13>=0.75, "مطلوب", IF(G13>=0.5, "متوسط", "نیازمند جهش"))) | J13: شیت سواد رسانه خلاقانه | K13: ایستگاه، نمایشگاه، رادیو، تبلیغات
B14: تولیدات رسانه‌ای و محتوایی | C14: ۳× به ازای هر حوزه | D14: =SUM('پایگاه داده حد انتظار'!$F$2:$F$33) | E14: =SUM('گزارش عملکرد ماهانه'!$E$2:$E$33) | F14: =E14-D14 | G14: =IFERROR(E14/D14, 0) | H14: =AVERAGE(O31:O62) | I14: =IF(G14>=1, "تحقق کامل", IF(G14>=0.75, "مطلوب", IF(G14>=0.5, "متوسط", "نیازمند جهش"))) | J14: شیت تولیدات | K14: کلیپ، اینفوگرافیک، موشن، پوستر
B15: نشست دبیر با انجمن مدرسان | C15: ۱ نشست به ازای ناحیه | D15: =SUM('پایگاه داده حد انتظار'!$G$2:$G$33) | E15: =SUM('گزارش عملکرد ماهانه'!$F$2:$F$33) | F15: =E15-D15 | G15: =IFERROR(E15/D15, 0) | H15: =AVERAGE(R31:R62) | I15: =IF(G15>=1, "تحقق کامل", IF(G15>=0.75, "مطلوب", IF(G15>=0.5, "متوسط", "نیازمند جهش"))) | J15: جلسات هماهنگی ناحیه | K15: نشست رسمی دبیر با مدرسان
B16: اعضای انجمن مدرسان | C16: ۲۲ نفر به ازای ناحیه | D16: =SUM('پایگاه داده حد انتظار'!$H$2:$H$33) | E16: - | F16: - | G16: - | H16: - | I16: ظرفیت‌سازی | J16: پایگاه حد انتظار | K16: مجموع ۷۰۴ عضو فعال استانی
B17: مجموع فعالیت‌های کلان استان | C17: - | D17: =SUM(D11:D15) | E17: =SUM(E11:E15) | F17: =E17-D17 | G17: =IFERROR(E17/D17, 0) | H17: =AVERAGE(G11:G15) | I17: =IF(G17>=1, "تحقق کامل", IF(G17>=0.75, "مطلوب", IF(G17>=0.5, "متوسط", "نیازمند جهش"))) | J17: ۵ شاخص اصلی | K17: مجموع ۷۱,۷۰۹ اقدام استانی
B20: 🏆 دیده‌بان برترین‌های عملکرد (۵ ناحیه پیشتاز استان اصفهان) | M20: ⚠️ دیده‌بان پیگیری و تقویت (۵ ناحیه با کمترین تحقق / نیازمند توجه)
B21: رتبه | C21: نام ناحیه (شهرستان) | D21: تعداد حوزه | E21: نمره کل عملکرد | F21: سطح ارزیابی | G21: وضعیت ثبت | H21: حضوری % | I21: مجازی % | J21: خلاقانه % | K21: تولیدات % | L21: نشست % | M21: اولویت | N21: نام ناحیه (شهرستان) | O21: تعداد حوزه | P21: نمره کل عملکرد | Q21: سطح ارزیابی | R21: وضعیت ثبت | S21: حضوری % | T21: مجازی % | U21: خلاقانه % | V21: اقدام پیشنهادی | W21: پیوند کارنامه
B22: 1 | C22: =IF(MAX($T$31:$T$62)>0, INDEX($B$31:$B$62, MATCH(LARGE($T$31:$T$62, 1), $T$31:$T$62, 0)), "در انتظار ثبت عملکرد") | D22: =IF(MAX($T$31:$T$62)>0, VLOOKUP(C22, $B$31:$C$62, 2, FALSE), "-") | E22: =IF(MAX($T$31:$T$62)>0, LARGE($T$31:$T$62, 1), 0) | F22: =IF(MAX($T$31:$T$62)>0, VLOOKUP(C22, $B$31:$V$62, 21, FALSE), "-") | G22: =IF(MAX($T$31:$T$62)>0, VLOOKUP(C22, $B$31:$W$62, 22, FALSE), "-") | H22: =IF(MAX($T$31:$T$62)>0, VLOOKUP(C22, $B$31:$F$62, 5, FALSE), "-") | I22: =IF(MAX($T$31:$T$62)>0, VLOOKUP(C22, $B$31:$I$62, 8, FALSE), "-") | J22: =IF(MAX($T$31:$T$62)>0, VLOOKUP(C22, $B$31:$L$62, 11, FALSE), "-") | K22: =IF(MAX($T$31:$T$62)>0, VLOOKUP(C22, $B$31:$O$62, 14, FALSE), "-") | L22: =IF(MAX($T$31:$T$62)>0, VLOOKUP(C22, $B$31:$R$62, 17, FALSE), "-") | M22: 1 | N22: =IF(MAX($T$31:$T$62)>0, INDEX($B$31:$B$62, MATCH(SMALL($T$31:$T$62, 1), $T$31:$T$62, 0)), "در انتظار ثبت عملکرد") | O22: =IF(MAX($T$31:$T$62)>0, VLOOKUP(N22, $B$31:$C$62, 2, FALSE), "-") | P22: =IF(MAX($T$31:$T$62)>0, SMALL($T$31:$T$62, 1), 0) | Q22: =IF(MAX($T$31:$T$62)>0, VLOOKUP(N22, $B$31:$V$62, 21, FALSE), "-") | R22: =IF(MAX($T$31:$T$62)>0, VLOOKUP(N22, $B$31:$W$62, 22, FALSE), "-") | S22: =IF(MAX($T$31:$T$62)>0, VLOOKUP(N22, $B$31:$F$62, 5, FALSE), "-") | T22: =IF(MAX($T$31:$T$62)>0, VLOOKUP(N22, $B$31:$I$62, 8, FALSE), "-") | U22: =IF(MAX($T$31:$T$62)>0, VLOOKUP(N22, $B$31:$L$62, 11, FALSE), "-") | V22: =IF(MAX($T$31:$T$62)>0, "پیگیری کسری عملکرد و کارگاه‌ها", "-") | W22: =HYPERLINK("#'کارنامه هوشمند'!A1", "مشاهده کارنامه ↗")
B23: 2 | C23: =IF(MAX($T$31:$T$62)>0, INDEX($B$31:$B$62, MATCH(LARGE($T$31:$T$62, 2), $T$31:$T$62, 0)), "در انتظار ثبت عملکرد") | D23: =IF(MAX($T$31:$T$62)>0, VLOOKUP(C23, $B$31:$C$62, 2, FALSE), "-") | E23: =IF(MAX($T$31:$T$62)>0, LARGE($T$31:$T$62, 2), 0) | F23: =IF(MAX($T$31:$T$62)>0, VLOOKUP(C23, $B$31:$V$62, 21, FALSE), "-") | G23: =IF(MAX($T$31:$T$62)>0, VLOOKUP(C23, $B$31:$W$62, 22, FALSE), "-") | H23: =IF(MAX($T$31:$T$62)>0, VLOOKUP(C23, $B$31:$F$62, 5, FALSE), "-") | I23: =IF(MAX($T$31:$T$62)>0, VLOOKUP(C23, $B$31:$I$62, 8, FALSE), "-") | J23: =IF(MAX($T$31:$T$62)>0, VLOOKUP(C23, $B$31:$L$62, 11, FALSE), "-") | K23: =IF(MAX($T$31:$T$62)>0, VLOOKUP(C23, $B$31:$O$62, 14, FALSE), "-") | L23: =IF(MAX($T$31:$T$62)>0, VLOOKUP(C23, $B$31:$R$62, 17, FALSE), "-") | M23: 2 | N23: =IF(MAX($T$31:$T$62)>0, INDEX($B$31:$B$62, MATCH(SMALL($T$31:$T$62, 2), $T$31:$T$62, 0)), "در انتظار ثبت عملکرد") | O23: =IF(MAX($T$31:$T$62)>0, VLOOKUP(N23, $B$31:$C$62, 2, FALSE), "-") | P23: =IF(MAX($T$31:$T$62)>0, SMALL($T$31:$T$62, 2), 0) | Q23: =IF(MAX($T$31:$T$62)>0, VLOOKUP(N23, $B$31:$V$62, 21, FALSE), "-") | R23: =IF(MAX($T$31:$T$62)>0, VLOOKUP(N23, $B$31:$W$62, 22, FALSE), "-") | S23: =IF(MAX($T$31:$T$62)>0, VLOOKUP(N23, $B$31:$F$62, 5, FALSE), "-") | T23: =IF(MAX($T$31:$T$62)>0, VLOOKUP(N23, $B$31:$I$62, 8, FALSE), "-") | U23: =IF(MAX($T$31:$T$62)>0, VLOOKUP(N23, $B$31:$L$62, 11, FALSE), "-") | V23: =IF(MAX($T$31:$T$62)>0, "پیگیری کسری عملکرد و کارگاه‌ها", "-") | W23: =HYPERLINK("#'کارنامه هوشمند'!A1", "مشاهده کارنامه ↗")
B24: 3 | C24: =IF(MAX($T$31:$T$62)>0, INDEX($B$31:$B$62, MATCH(LARGE($T$31:$T$62, 3), $T$31:$T$62, 0)), "در انتظار ثبت عملکرد") | D24: =IF(MAX($T$31:$T$62)>0, VLOOKUP(C24, $B$31:$C$62, 2, FALSE), "-") | E24: =IF(MAX($T$31:$T$62)>0, LARGE($T$31:$T$62, 3), 0) | F24: =IF(MAX($T$31:$T$62)>0, VLOOKUP(C24, $B$31:$V$62, 21, FALSE), "-") | G24: =IF(MAX($T$31:$T$62)>0, VLOOKUP(C24, $B$31:$W$62, 22, FALSE), "-") | H24: =IF(MAX($T$31:$T$62)>0, VLOOKUP(C24, $B$31:$F$62, 5, FALSE), "-") | I24: =IF(MAX($T$31:$T$62)>0, VLOOKUP(C24, $B$31:$I$62, 8, FALSE), "-") | J24: =IF(MAX($T$31:$T$62)>0, VLOOKUP(C24, $B$31:$L$62, 11, FALSE), "-") | K24: =IF(MAX($T$31:$T$62)>0, VLOOKUP(C24, $B$31:$O$62, 14, FALSE), "-") | L24: =IF(MAX($T$31:$T$62)>0, VLOOKUP(C24, $B$31:$R$62, 17, FALSE), "-") | M24: 3 | N24: =IF(MAX($T$31:$T$62)>0, INDEX($B$31:$B$62, MATCH(SMALL($T$31:$T$62, 3), $T$31:$T$62, 0)), "در انتظار ثبت عملکرد") | O24: =IF(MAX($T$31:$T$62)>0, VLOOKUP(N24, $B$31:$C$62, 2, FALSE), "-") | P24: =IF(MAX($T$31:$T$62)>0, SMALL($T$31:$T$62, 3), 0) | Q24: =IF(MAX($T$31:$T$62)>0, VLOOKUP(N24, $B$31:$V$62, 21, FALSE), "-") | R24: =IF(MAX($T$31:$T$62)>0, VLOOKUP(N24, $B$31:$W$62, 22, FALSE), "-") | S24: =IF(MAX($T$31:$T$62)>0, VLOOKUP(N24, $B$31:$F$62, 5, FALSE), "-") | T24: =IF(MAX($T$31:$T$62)>0, VLOOKUP(N24, $B$31:$I$62, 8, FALSE), "-") | U24: =IF(MAX($T$31:$T$62)>0, VLOOKUP(N24, $B$31:$L$62, 11, FALSE), "-") | V24: =IF(MAX($T$31:$T$62)>0, "پیگیری کسری عملکرد و کارگاه‌ها", "-") | W24: =HYPERLINK("#'کارنامه هوشمند'!A1", "مشاهده کارنامه ↗")
B25: 4 | C25: =IF(MAX($T$31:$T$62)>0, INDEX($B$31:$B$62, MATCH(LARGE($T$31:$T$62, 4), $T$31:$T$62, 0)), "در انتظار ثبت عملکرد") | D25: =IF(MAX($T$31:$T$62)>0, VLOOKUP(C25, $B$31:$C$62, 2, FALSE), "-") | E25: =IF(MAX($T$31:$T$62)>0, LARGE($T$31:$T$62, 4), 0) | F25: =IF(MAX($T$31:$T$62)>0, VLOOKUP(C25, $B$31:$V$62, 21, FALSE), "-") | G25: =IF(MAX($T$31:$T$62)>0, VLOOKUP(C25, $B$31:$W$62, 22, FALSE), "-") | H25: =IF(MAX($T$31:$T$62)>0, VLOOKUP(C25, $B$31:$F$62, 5, FALSE), "-") | I25: =IF(MAX($T$31:$T$62)>0, VLOOKUP(C25, $B$31:$I$62, 8, FALSE), "-") | J25: =IF(MAX($T$31:$T$62)>0, VLOOKUP(C25, $B$31:$L$62, 11, FALSE), "-") | K25: =IF(MAX($T$31:$T$62)>0, VLOOKUP(C25, $B$31:$O$62, 14, FALSE), "-") | L25: =IF(MAX($T$31:$T$62)>0, VLOOKUP(C25, $B$31:$R$62, 17, FALSE), "-") | M25: 4 | N25: =IF(MAX($T$31:$T$62)>0, INDEX($B$31:$B$62, MATCH(SMALL($T$31:$T$62, 4), $T$31:$T$62, 0)), "در انتظار ثبت عملکرد") | O25: =IF(MAX($T$31:$T$62)>0, VLOOKUP(N25, $B$31:$C$62, 2, FALSE), "-") | P25: =IF(MAX($T$31:$T$62)>0, SMALL($T$31:$T$62, 4), 0) | Q25: =IF(MAX($T$31:$T$62)>0, VLOOKUP(N25, $B$31:$V$62, 21, FALSE), "-") | R25: =IF(MAX($T$31:$T$62)>0, VLOOKUP(N25, $B$31:$W$62, 22, FALSE), "-") | S25: =IF(MAX($T$31:$T$62)>0, VLOOKUP(N25, $B$31:$F$62, 5, FALSE), "-") | T25: =IF(MAX($T$31:$T$62)>0, VLOOKUP(N25, $B$31:$I$62, 8, FALSE), "-") | U25: =IF(MAX($T$31:$T$62)>0, VLOOKUP(N25, $B$31:$L$62, 11, FALSE), "-") | V25: =IF(MAX($T$31:$T$62)>0, "پیگیری کسری عملکرد و کارگاه‌ها", "-") | W25: =HYPERLINK("#'کارنامه هوشمند'!A1", "مشاهده کارنامه ↗")
B26: 5 | C26: =IF(MAX($T$31:$T$62)>0, INDEX($B$31:$B$62, MATCH(LARGE($T$31:$T$62, 5), $T$31:$T$62, 0)), "در انتظار ثبت عملکرد") | D26: =IF(MAX($T$31:$T$62)>0, VLOOKUP(C26, $B$31:$C$62, 2, FALSE), "-") | E26: =IF(MAX($T$31:$T$62)>0, LARGE($T$31:$T$62, 5), 0) | F26: =IF(MAX($T$31:$T$62)>0, VLOOKUP(C26, $B$31:$V$62, 21, FALSE), "-") | G26: =IF(MAX($T$31:$T$62)>0, VLOOKUP(C26, $B$31:$W$62, 22, FALSE), "-") | H26: =IF(MAX($T$31:$T$62)>0, VLOOKUP(C26, $B$31:$F$62, 5, FALSE), "-") | I26: =IF(MAX($T$31:$T$62)>0, VLOOKUP(C26, $B$31:$I$62, 8, FALSE), "-") | J26: =IF(MAX($T$31:$T$62)>0, VLOOKUP(C26, $B$31:$L$62, 11, FALSE), "-") | K26: =IF(MAX($T$31:$T$62)>0, VLOOKUP(C26, $B$31:$O$62, 14, FALSE), "-") | L26: =IF(MAX($T$31:$T$62)>0, VLOOKUP(C26, $B$31:$R$62, 17, FALSE), "-") | M26: 5 | N26: =IF(MAX($T$31:$T$62)>0, INDEX($B$31:$B$62, MATCH(SMALL($T$31:$T$62, 5), $T$31:$T$62, 0)), "در انتظار ثبت عملکرد") | O26: =IF(MAX($T$31:$T$62)>0, VLOOKUP(N26, $B$31:$C$62, 2, FALSE), "-") | P26: =IF(MAX($T$31:$T$62)>0, SMALL($T$31:$T$62, 5), 0) | Q26: =IF(MAX($T$31:$T$62)>0, VLOOKUP(N26, $B$31:$V$62, 21, FALSE), "-") | R26: =IF(MAX($T$31:$T$62)>0, VLOOKUP(N26, $B$31:$W$62, 22, FALSE), "-") | S26: =IF(MAX($T$31:$T$62)>0, VLOOKUP(N26, $B$31:$F$62, 5, FALSE), "-") | T26: =IF(MAX($T$31:$T$62)>0, VLOOKUP(N26, $B$31:$I$62, 8, FALSE), "-") | U26: =IF(MAX($T$31:$T$62)>0, VLOOKUP(N26, $B$31:$L$62, 11, FALSE), "-") | V26: =IF(MAX($T$31:$T$62)>0, "پیگیری کسری عملکرد و کارگاه‌ها", "-") | W26: =HYPERLINK("#'کارنامه هوشمند'!A1", "مشاهده کارنامه ↗")
A28: ۲. جدول جامع رصد و مانیتورینگ عملکرد ۳۲ ناحیه و کارمند استان اصفهان (تفکیک شاخص‌ها و حوزه‌ها)
A29: مشخصات کلی ناحیه | D29: ۱. حضوری و توانمندسازی (۳۱×) | G29: ۲. مجازی و لایو (۲۱۷×) | J29: ۳. اقدامات خلاقانه (۶۲×) | M29: ۴. تولیدات رسانه‌ای (۳×) | P29: ۵. نشست انجمن (۱×) | S29: ۶. اعضا | T29: ارزیابی نهایی و رتبه‌بندی استانی
A30: ردیف | B30: نام ناحیه (شهرستان) | C30: تعداد حوزه | D30: حد انتظار | E30: عملکرد | F30: درصد تحقق | G30: حد انتظار | H30: عملکرد | I30: درصد تحقق | J30: حد انتظار | K30: عملکرد | L30: درصد تحقق | M30: حد انتظار | N30: عملکرد | O30: درصد تحقق | P30: حد انتظار | Q30: عملکرد | R30: درصد تحقق | S30: اعضای انجمن | T30: نمره کل عملکرد (۷۰-۱۰۰) | U30: رتبه استانی | V30: سطح ارزیابی (۳ سطح) | W30: وضعیت گزارش
A31: 1 | B31: آران و بیدگل | C31: =VLOOKUP($B31, 'پایگاه داده حد انتظار'!$A$2:$H$33, 2, FALSE) | D31: =VLOOKUP($B31, 'پایگاه داده حد انتظار'!$A$2:$H$33, 3, FALSE) | E31: =IFERROR(VLOOKUP($B31, 'گزارش عملکرد ماهانه'!$A$2:$F$33, 2, FALSE), 0) | F31: =IFERROR(E31/D31, 0) | G31: =VLOOKUP($B31, 'پایگاه داده حد انتظار'!$A$2:$H$33, 4, FALSE) | H31: =IFERROR(VLOOKUP($B31, 'گزارش عملکرد ماهانه'!$A$2:$F$33, 3, FALSE), 0) | I31: =IFERROR(H31/G31, 0) | J31: =VLOOKUP($B31, 'پایگاه داده حد انتظار'!$A$2:$H$33, 5, FALSE) | K31: =IFERROR(VLOOKUP($B31, 'گزارش عملکرد ماهانه'!$A$2:$F$33, 4, FALSE), 0) | L31: =IFERROR(K31/J31, 0) | M31: =VLOOKUP($B31, 'پایگاه داده حد انتظار'!$A$2:$H$33, 6, FALSE) | N31: =IFERROR(VLOOKUP($B31, 'گزارش عملکرد ماهانه'!$A$2:$F$33, 5, FALSE), 0) | O31: =IFERROR(N31/M31, 0) | P31: =VLOOKUP($B31, 'پایگاه داده حد انتظار'!$A$2:$H$33, 7, FALSE) | Q31: =IFERROR(VLOOKUP($B31, 'گزارش عملکرد ماهانه'!$A$2:$F$33, 6, FALSE), 0) | R31: =IFERROR(Q31/P31, 0) | S31: =VLOOKUP($B31, 'پایگاه داده حد انتظار'!$A$2:$H$33, 8, FALSE) | T31: =ROUND(70 + 30 * (MIN(0.4, 0.1*F31 + 0.3*I31) + MIN(0.5, 0.5*L31 + MAX(0, 0.1*F31 + 0.3*I31 - 0.4)) + MIN(0.1, 0.1*O31)), 1) | U31: =IF(T31>70, RANK(T31, $T$31:$T$62), "-") | V31: =IF(T31<=70, "ضعیف", IF(T31>=90, "عالی", "متوسط")) | W31: =IF((E31+H31+K31+N31+Q31)>0, "ثبت شده", "فاقد گزارش")
A32: 2 | B32: امام حسین(ع) | C32: =VLOOKUP($B32, 'پایگاه داده حد انتظار'!$A$2:$H$33, 2, FALSE) | D32: =VLOOKUP($B32, 'پایگاه داده حد انتظار'!$A$2:$H$33, 3, FALSE) | E32: =IFERROR(VLOOKUP($B32, 'گزارش عملکرد ماهانه'!$A$2:$F$33, 2, FALSE), 0) | F32: =IFERROR(E32/D32, 0) | G32: =VLOOKUP($B32, 'پایگاه داده حد انتظار'!$A$2:$H$33, 4, FALSE) | H32: =IFERROR(VLOOKUP($B32, 'گزارش عملکرد ماهانه'!$A$2:$F$33, 3, FALSE), 0) | I32: =IFERROR(H32/G32, 0) | J32: =VLOOKUP($B32, 'پایگاه داده حد انتظار'!$A$2:$H$33, 5, FALSE) | K32: =IFERROR(VLOOKUP($B32, 'گزارش عملکرد ماهانه'!$A$2:$F$33, 4, FALSE), 0) | L32: =IFERROR(K32/J32, 0) | M32: =VLOOKUP($B32, 'پایگاه داده حد انتظار'!$A$2:$H$33, 6, FALSE) | N32: =IFERROR(VLOOKUP($B32, 'گزارش عملکرد ماهانه'!$A$2:$F$33, 5, FALSE), 0) | O32: =IFERROR(N32/M32, 0) | P32: =VLOOKUP($B32, 'پایگاه داده حد انتظار'!$A$2:$H$33, 7, FALSE) | Q32: =IFERROR(VLOOKUP($B32, 'گزارش عملکرد ماهانه'!$A$2:$F$33, 6, FALSE), 0) | R32: =IFERROR(Q32/P32, 0) | S32: =VLOOKUP($B32, 'پایگاه داده حد انتظار'!$A$2:$H$33, 8, FALSE) | T32: =ROUND(70 + 30 * (MIN(0.4, 0.1*F32 + 0.3*I32) + MIN(0.5, 0.5*L32 + MAX(0, 0.1*F32 + 0.3*I32 - 0.4)) + MIN(0.1, 0.1*O32)), 1) | U32: =IF(T32>70, RANK(T32, $T$31:$T$62), "-") | V32: =IF(T32<=70, "ضعیف", IF(T32>=90, "عالی", "متوسط")) | W32: =IF((E32+H32+K32+N32+Q32)>0, "ثبت شده", "فاقد گزارش")
A33: 3 | B33: امام رضا(ع) | C33: =VLOOKUP($B33, 'پایگاه داده حد انتظار'!$A$2:$H$33, 2, FALSE) | D33: =VLOOKUP($B33, 'پایگاه داده حد انتظار'!$A$2:$H$33, 3, FALSE) | E33: =IFERROR(VLOOKUP($B33, 'گزارش عملکرد ماهانه'!$A$2:$F$33, 2, FALSE), 0) | F33: =IFERROR(E33/D33, 0) | G33: =VLOOKUP($B33, 'پایگاه داده حد انتظار'!$A$2:$H$33, 4, FALSE) | H33: =IFERROR(VLOOKUP($B33, 'گزارش عملکرد ماهانه'!$A$2:$F$33, 3, FALSE), 0) | I33: =IFERROR(H33/G33, 0) | J33: =VLOOKUP($B33, 'پایگاه داده حد انتظار'!$A$2:$H$33, 5, FALSE) | K33: =IFERROR(VLOOKUP($B33, 'گزارش عملکرد ماهانه'!$A$2:$F$33, 4, FALSE), 0) | L33: =IFERROR(K33/J33, 0) | M33: =VLOOKUP($B33, 'پایگاه داده حد انتظار'!$A$2:$H$33, 6, FALSE) | N33: =IFERROR(VLOOKUP($B33, 'گزارش عملکرد ماهانه'!$A$2:$F$33, 5, FALSE), 0) | O33: =IFERROR(N33/M33, 0) | P33: =VLOOKUP($B33, 'پایگاه داده حد انتظار'!$A$2:$H$33, 7, FALSE) | Q33: =IFERROR(VLOOKUP($B33, 'گزارش عملکرد ماهانه'!$A$2:$F$33, 6, FALSE), 0) | R33: =IFERROR(Q33/P33, 0) | S33: =VLOOKUP($B33, 'پایگاه داده حد انتظار'!$A$2:$H$33, 8, FALSE) | T33: =ROUND(70 + 30 * (MIN(0.4, 0.1*F33 + 0.3*I33) + MIN(0.5, 0.5*L33 + MAX(0, 0.1*F33 + 0.3*I33 - 0.4)) + MIN(0.1, 0.1*O33)), 1) | U33: =IF(T33>70, RANK(T33, $T$31:$T$62), "-") | V33: =IF(T33<=70, "ضعیف", IF(T33>=90, "عالی", "متوسط")) | W33: =IF((E33+H33+K33+N33+Q33)>0, "ثبت شده", "فاقد گزارش")
A34: 4 | B34: امام صادق(ع) | C34: =VLOOKUP($B34, 'پایگاه داده حد انتظار'!$A$2:$H$33, 2, FALSE) | D34: =VLOOKUP($B34, 'پایگاه داده حد انتظار'!$A$2:$H$33, 3, FALSE) | E34: =IFERROR(VLOOKUP($B34, 'گزارش عملکرد ماهانه'!$A$2:$F$33, 2, FALSE), 0) | F34: =IFERROR(E34/D34, 0) | G34: =VLOOKUP($B34, 'پایگاه داده حد انتظار'!$A$2:$H$33, 4, FALSE) | H34: =IFERROR(VLOOKUP($B34, 'گزارش عملکرد ماهانه'!$A$2:$F$33, 3, FALSE), 0) | I34: =IFERROR(H34/G34, 0) | J34: =VLOOKUP($B34, 'پایگاه داده حد انتظار'!$A$2:$H$33, 5, FALSE) | K34: =IFERROR(VLOOKUP($B34, 'گزارش عملکرد ماهانه'!$A$2:$F$33, 4, FALSE), 0) | L34: =IFERROR(K34/J34, 0) | M34: =VLOOKUP($B34, 'پایگاه داده حد انتظار'!$A$2:$H$33, 6, FALSE) | N34: =IFERROR(VLOOKUP($B34, 'گزارش عملکرد ماهانه'!$A$2:$F$33, 5, FALSE), 0) | O34: =IFERROR(N34/M34, 0) | P34: =VLOOKUP($B34, 'پایگاه داده حد انتظار'!$A$2:$H$33, 7, FALSE) | Q34: =IFERROR(VLOOKUP($B34, 'گزارش عملکرد ماهانه'!$A$2:$F$33, 6, FALSE), 0) | R34: =IFERROR(Q34/P34, 0) | S34: =VLOOKUP($B34, 'پایگاه داده حد انتظار'!$A$2:$H$33, 8, FALSE) | T34: =ROUND(70 + 30 * (MIN(0.4, 0.1*F34 + 0.3*I34) + MIN(0.5, 0.5*L34 + MAX(0, 0.1*F34 + 0.3*I34 - 0.4)) + MIN(0.1, 0.1*O34)), 1) | U34: =IF(T34>70, RANK(T34, $T$31:$T$62), "-") | V34: =IF(T34<=70, "ضعیف", IF(T34>=90, "عالی", "متوسط")) | W34: =IF((E34+H34+K34+N34+Q34)>0, "ثبت شده", "فاقد گزارش")
A35: 5 | B35: امام علی(ع) | C35: =VLOOKUP($B35, 'پایگاه داده حد انتظار'!$A$2:$H$33, 2, FALSE) | D35: =VLOOKUP($B35, 'پایگاه داده حد انتظار'!$A$2:$H$33, 3, FALSE) | E35: =IFERROR(VLOOKUP($B35, 'گزارش عملکرد ماهانه'!$A$2:$F$33, 2, FALSE), 0) | F35: =IFERROR(E35/D35, 0) | G35: =VLOOKUP($B35, 'پایگاه داده حد انتظار'!$A$2:$H$33, 4, FALSE) | H35: =IFERROR(VLOOKUP($B35, 'گزارش عملکرد ماهانه'!$A$2:$F$33, 3, FALSE), 0) | I35: =IFERROR(H35/G35, 0) | J35: =VLOOKUP($B35, 'پایگاه داده حد انتظار'!$A$2:$H$33, 5, FALSE) | K35: =IFERROR(VLOOKUP($B35, 'گزارش عملکرد ماهانه'!$A$2:$F$33, 4, FALSE), 0) | L35: =IFERROR(K35/J35, 0) | M35: =VLOOKUP($B35, 'پایگاه داده حد انتظار'!$A$2:$H$33, 6, FALSE) | N35: =IFERROR(VLOOKUP($B35, 'گزارش عملکرد ماهانه'!$A$2:$F$33, 5, FALSE), 0) | O35: =IFERROR(N35/M35, 0) | P35: =VLOOKUP($B35, 'پایگاه داده حد انتظار'!$A$2:$H$33, 7, FALSE) | Q35: =IFERROR(VLOOKUP($B35, 'گزارش عملکرد ماهانه'!$A$2:$F$33, 6, FALSE), 0) | R35: =IFERROR(Q35/P35, 0) | S35: =VLOOKUP($B35, 'پایگاه داده حد انتظار'!$A$2:$H$33, 8, FALSE) | T35: =ROUND(70 + 30 * (MIN(0.4, 0.1*F35 + 0.3*I35) + MIN(0.5, 0.5*L35 + MAX(0, 0.1*F35 + 0.3*I35 - 0.4)) + MIN(0.1, 0.1*O35)), 1) | U35: =IF(T35>70, RANK(T35, $T$31:$T$62), "-") | V35: =IF(T35<=70, "ضعیف", IF(T35>=90, "عالی", "متوسط")) | W35: =IF((E35+H35+K35+N35+Q35)>0, "ثبت شده", "فاقد گزارش")
A36: 6 | B36: اردستان | C36: =VLOOKUP($B36, 'پایگاه داده حد انتظار'!$A$2:$H$33, 2, FALSE) | D36: =VLOOKUP($B36, 'پایگاه داده حد انتظار'!$A$2:$H$33, 3, FALSE) | E36: =IFERROR(VLOOKUP($B36, 'گزارش عملکرد ماهانه'!$A$2:$F$33, 2, FALSE), 0) | F36: =IFERROR(E36/D36, 0) | G36: =VLOOKUP($B36, 'پایگاه داده حد انتظار'!$A$2:$H$33, 4, FALSE) | H36: =IFERROR(VLOOKUP($B36, 'گزارش عملکرد ماهانه'!$A$2:$F$33, 3, FALSE), 0) | I36: =IFERROR(H36/G36, 0) | J36: =VLOOKUP($B36, 'پایگاه داده حد انتظار'!$A$2:$H$33, 5, FALSE) | K36: =IFERROR(VLOOKUP($B36, 'گزارش عملکرد ماهانه'!$A$2:$F$33, 4, FALSE), 0) | L36: =IFERROR(K36/J36, 0) | M36: =VLOOKUP($B36, 'پایگاه داده حد انتظار'!$A$2:$H$33, 6, FALSE) | N36: =IFERROR(VLOOKUP($B36, 'گزارش عملکرد ماهانه'!$A$2:$F$33, 5, FALSE), 0) | O36: =IFERROR(N36/M36, 0) | P36: =VLOOKUP($B36, 'پایگاه داده حد انتظار'!$A$2:$H$33, 7, FALSE) | Q36: =IFERROR(VLOOKUP($B36, 'گزارش عملکرد ماهانه'!$A$2:$F$33, 6, FALSE), 0) | R36: =IFERROR(Q36/P36, 0) | S36: =VLOOKUP($B36, 'پایگاه داده حد انتظار'!$A$2:$H$33, 8, FALSE) | T36: =ROUND(70 + 30 * (MIN(0.4, 0.1*F36 + 0.3*I36) + MIN(0.5, 0.5*L36 + MAX(0, 0.1*F36 + 0.3*I36 - 0.4)) + MIN(0.1, 0.1*O36)), 1) | U36: =IF(T36>70, RANK(T36, $T$31:$T$62), "-") | V36: =IF(T36<=70, "ضعیف", IF(T36>=90, "عالی", "متوسط")) | W36: =IF((E36+H36+K36+N36+Q36)>0, "ثبت شده", "فاقد گزارش")
A37: 7 | B37: برخوار | C37: =VLOOKUP($B37, 'پایگاه داده حد انتظار'!$A$2:$H$33, 2, FALSE) | D37: =VLOOKUP($B37, 'پایگاه داده حد انتظار'!$A$2:$H$33, 3, FALSE) | E37: =IFERROR(VLOOKUP($B37, 'گزارش عملکرد ماهانه'!$A$2:$F$33, 2, FALSE), 0) | F37: =IFERROR(E37/D37, 0) | G37: =VLOOKUP($B37, 'پایگاه داده حد انتظار'!$A$2:$H$33, 4, FALSE) | H37: =IFERROR(VLOOKUP($B37, 'گزارش عملکرد ماهانه'!$A$2:$F$33, 3, FALSE), 0) | I37: =IFERROR(H37/G37, 0) | J37: =VLOOKUP($B37, 'پایگاه داده حد انتظار'!$A$2:$H$33, 5, FALSE) | K37: =IFERROR(VLOOKUP($B37, 'گزارش عملکرد ماهانه'!$A$2:$F$33, 4, FALSE), 0) | L37: =IFERROR(K37/J37, 0) | M37: =VLOOKUP($B37, 'پایگاه داده حد انتظار'!$A$2:$H$33, 6, FALSE) | N37: =IFERROR(VLOOKUP($B37, 'گزارش عملکرد ماهانه'!$A$2:$F$33, 5, FALSE), 0) | O37: =IFERROR(N37/M37, 0) | P37: =VLOOKUP($B37, 'پایگاه داده حد انتظار'!$A$2:$H$33, 7, FALSE) | Q37: =IFERROR(VLOOKUP($B37, 'گزارش عملکرد ماهانه'!$A$2:$F$33, 6, FALSE), 0) | R37: =IFERROR(Q37/P37, 0) | S37: =VLOOKUP($B37, 'پایگاه داده حد انتظار'!$A$2:$H$33, 8, FALSE) | T37: =ROUND(70 + 30 * (MIN(0.4, 0.1*F37 + 0.3*I37) + MIN(0.5, 0.5*L37 + MAX(0, 0.1*F37 + 0.3*I37 - 0.4)) + MIN(0.1, 0.1*O37)), 1) | U37: =IF(T37>70, RANK(T37, $T$31:$T$62), "-") | V37: =IF(T37<=70, "ضعیف", IF(T37>=90, "عالی", "متوسط")) | W37: =IF((E37+H37+K37+N37+Q37)>0, "ثبت شده", "فاقد گزارش")
A38: 8 | B38: بویین و میاندشت | C38: =VLOOKUP($B38, 'پایگاه داده حد انتظار'!$A$2:$H$33, 2, FALSE) | D38: =VLOOKUP($B38, 'پایگاه داده حد انتظار'!$A$2:$H$33, 3, FALSE) | E38: =IFERROR(VLOOKUP($B38, 'گزارش عملکرد ماهانه'!$A$2:$F$33, 2, FALSE), 0) | F38: =IFERROR(E38/D38, 0) | G38: =VLOOKUP($B38, 'پایگاه داده حد انتظار'!$A$2:$H$33, 4, FALSE) | H38: =IFERROR(VLOOKUP($B38, 'گزارش عملکرد ماهانه'!$A$2:$F$33, 3, FALSE), 0) | I38: =IFERROR(H38/G38, 0) | J38: =VLOOKUP($B38, 'پایگاه داده حد انتظار'!$A$2:$H$33, 5, FALSE) | K38: =IFERROR(VLOOKUP($B38, 'گزارش عملکرد ماهانه'!$A$2:$F$33, 4, FALSE), 0) | L38: =IFERROR(K38/J38, 0) | M38: =VLOOKUP($B38, 'پایگاه داده حد انتظار'!$A$2:$H$33, 6, FALSE) | N38: =IFERROR(VLOOKUP($B38, 'گزارش عملکرد ماهانه'!$A$2:$F$33, 5, FALSE), 0) | O38: =IFERROR(N38/M38, 0) | P38: =VLOOKUP($B38, 'پایگاه داده حد انتظار'!$A$2:$H$33, 7, FALSE) | Q38: =IFERROR(VLOOKUP($B38, 'گزارش عملکرد ماهانه'!$A$2:$F$33, 6, FALSE), 0) | R38: =IFERROR(Q38/P38, 0) | S38: =VLOOKUP($B38, 'پایگاه داده حد انتظار'!$A$2:$H$33, 8, FALSE) | T38: =ROUND(70 + 30 * (MIN(0.4, 0.1*F38 + 0.3*I38) + MIN(0.5, 0.5*L38 + MAX(0, 0.1*F38 + 0.3*I38 - 0.4)) + MIN(0.1, 0.1*O38)), 1) | U38: =IF(T38>70, RANK(T38, $T$31:$T$62), "-") | V38: =IF(T38<=70, "ضعیف", IF(T38>=90, "عالی", "متوسط")) | W38: =IF((E38+H38+K38+N38+Q38)>0, "ثبت شده", "فاقد گزارش")
A39: 9 | B39: تیران و کرون | C39: =VLOOKUP($B39, 'پایگاه داده حد انتظار'!$A$2:$H$33, 2, FALSE) | D39: =VLOOKUP($B39, 'پایگاه داده حد انتظار'!$A$2:$H$33, 3, FALSE) | E39: =IFERROR(VLOOKUP($B39, 'گزارش عملکرد ماهانه'!$A$2:$F$33, 2, FALSE), 0) | F39: =IFERROR(E39/D39, 0) | G39: =VLOOKUP($B39, 'پایگاه داده حد انتظار'!$A$2:$H$33, 4, FALSE) | H39: =IFERROR(VLOOKUP($B39, 'گزارش عملکرد ماهانه'!$A$2:$F$33, 3, FALSE), 0) | I39: =IFERROR(H39/G39, 0) | J39: =VLOOKUP($B39, 'پایگاه داده حد انتظار'!$A$2:$H$33, 5, FALSE) | K39: =IFERROR(VLOOKUP($B39, 'گزارش عملکرد ماهانه'!$A$2:$F$33, 4, FALSE), 0) | L39: =IFERROR(K39/J39, 0) | M39: =VLOOKUP($B39, 'پایگاه داده حد انتظار'!$A$2:$H$33, 6, FALSE) | N39: =IFERROR(VLOOKUP($B39, 'گزارش عملکرد ماهانه'!$A$2:$F$33, 5, FALSE), 0) | O39: =IFERROR(N39/M39, 0) | P39: =VLOOKUP($B39, 'پایگاه داده حد انتظار'!$A$2:$H$33, 7, FALSE) | Q39: =IFERROR(VLOOKUP($B39, 'گزارش عملکرد ماهانه'!$A$2:$F$33, 6, FALSE), 0) | R39: =IFERROR(Q39/P39, 0) | S39: =VLOOKUP($B39, 'پایگاه داده حد انتظار'!$A$2:$H$33, 8, FALSE) | T39: =ROUND(70 + 30 * (MIN(0.4, 0.1*F39 + 0.3*I39) + MIN(0.5, 0.5*L39 + MAX(0, 0.1*F39 + 0.3*I39 - 0.4)) + MIN(0.1, 0.1*O39)), 1) | U39: =IF(T39>70, RANK(T39, $T$31:$T$62), "-") | V39: =IF(T39<=70, "ضعیف", IF(T39>=90, "عالی", "متوسط")) | W39: =IF((E39+H39+K39+N39+Q39)>0, "ثبت شده", "فاقد گزارش")
A40: 10 | B40: جرقویه | C40: =VLOOKUP($B40, 'پایگاه داده حد انتظار'!$A$2:$H$33, 2, FALSE) | D40: =VLOOKUP($B40, 'پایگاه داده حد انتظار'!$A$2:$H$33, 3, FALSE) | E40: =IFERROR(VLOOKUP($B40, 'گزارش عملکرد ماهانه'!$A$2:$F$33, 2, FALSE), 0) | F40: =IFERROR(E40/D40, 0) | G40: =VLOOKUP($B40, 'پایگاه داده حد انتظار'!$A$2:$H$33, 4, FALSE) | H40: =IFERROR(VLOOKUP($B40, 'گزارش عملکرد ماهانه'!$A$2:$F$33, 3, FALSE), 0) | I40: =IFERROR(H40/G40, 0) | J40: =VLOOKUP($B40, 'پایگاه داده حد انتظار'!$A$2:$H$33, 5, FALSE) | K40: =IFERROR(VLOOKUP($B40, 'گزارش عملکرد ماهانه'!$A$2:$F$33, 4, FALSE), 0) | L40: =IFERROR(K40/J40, 0) | M40: =VLOOKUP($B40, 'پایگاه داده حد انتظار'!$A$2:$H$33, 6, FALSE) | N40: =IFERROR(VLOOKUP($B40, 'گزارش عملکرد ماهانه'!$A$2:$F$33, 5, FALSE), 0) | O40: =IFERROR(N40/M40, 0) | P40: =VLOOKUP($B40, 'پایگاه داده حد انتظار'!$A$2:$H$33, 7, FALSE) | Q40: =IFERROR(VLOOKUP($B40, 'گزارش عملکرد ماهانه'!$A$2:$F$33, 6, FALSE), 0) | R40: =IFERROR(Q40/P40, 0) | S40: =VLOOKUP($B40, 'پایگاه داده حد انتظار'!$A$2:$H$33, 8, FALSE) | T40: =ROUND(70 + 30 * (MIN(0.4, 0.1*F40 + 0.3*I40) + MIN(0.5, 0.5*L40 + MAX(0, 0.1*F40 + 0.3*I40 - 0.4)) + MIN(0.1, 0.1*O40)), 1) | U40: =IF(T40>70, RANK(T40, $T$31:$T$62), "-") | V40: =IF(T40<=70, "ضعیف", IF(T40>=90, "عالی", "متوسط")) | W40: =IF((E40+H40+K40+N40+Q40)>0, "ثبت شده", "فاقد گزارش")
A41: 11 | B41: چادگان | C41: =VLOOKUP($B41, 'پایگاه داده حد انتظار'!$A$2:$H$33, 2, FALSE) | D41: =VLOOKUP($B41, 'پایگاه داده حد انتظار'!$A$2:$H$33, 3, FALSE) | E41: =IFERROR(VLOOKUP($B41, 'گزارش عملکرد ماهانه'!$A$2:$F$33, 2, FALSE), 0) | F41: =IFERROR(E41/D41, 0) | G41: =VLOOKUP($B41, 'پایگاه داده حد انتظار'!$A$2:$H$33, 4, FALSE) | H41: =IFERROR(VLOOKUP($B41, 'گزارش عملکرد ماهانه'!$A$2:$F$33, 3, FALSE), 0) | I41: =IFERROR(H41/G41, 0) | J41: =VLOOKUP($B41, 'پایگاه داده حد انتظار'!$A$2:$H$33, 5, FALSE) | K41: =IFERROR(VLOOKUP($B41, 'گزارش عملکرد ماهانه'!$A$2:$F$33, 4, FALSE), 0) | L41: =IFERROR(K41/J41, 0) | M41: =VLOOKUP($B41, 'پایگاه داده حد انتظار'!$A$2:$H$33, 6, FALSE) | N41: =IFERROR(VLOOKUP($B41, 'گزارش عملکرد ماهانه'!$A$2:$F$33, 5, FALSE), 0) | O41: =IFERROR(N41/M41, 0) | P41: =VLOOKUP($B41, 'پایگاه داده حد انتظار'!$A$2:$H$33, 7, FALSE) | Q41: =IFERROR(VLOOKUP($B41, 'گزارش عملکرد ماهانه'!$A$2:$F$33, 6, FALSE), 0) | R41: =IFERROR(Q41/P41, 0) | S41: =VLOOKUP($B41, 'پایگاه داده حد انتظار'!$A$2:$H$33, 8, FALSE) | T41: =ROUND(70 + 30 * (MIN(0.4, 0.1*F41 + 0.3*I41) + MIN(0.5, 0.5*L41 + MAX(0, 0.1*F41 + 0.3*I41 - 0.4)) + MIN(0.1, 0.1*O41)), 1) | U41: =IF(T41>70, RANK(T41, $T$31:$T$62), "-") | V41: =IF(T41<=70, "ضعیف", IF(T41>=90, "عالی", "متوسط")) | W41: =IF((E41+H41+K41+N41+Q41)>0, "ثبت شده", "فاقد گزارش")
A42: 12 | B42: خمینی شهر | C42: =VLOOKUP($B42, 'پایگاه داده حد انتظار'!$A$2:$H$33, 2, FALSE) | D42: =VLOOKUP($B42, 'پایگاه داده حد انتظار'!$A$2:$H$33, 3, FALSE) | E42: =IFERROR(VLOOKUP($B42, 'گزارش عملکرد ماهانه'!$A$2:$F$33, 2, FALSE), 0) | F42: =IFERROR(E42/D42, 0) | G42: =VLOOKUP($B42, 'پایگاه داده حد انتظار'!$A$2:$H$33, 4, FALSE) | H42: =IFERROR(VLOOKUP($B42, 'گزارش عملکرد ماهانه'!$A$2:$F$33, 3, FALSE), 0) | I42: =IFERROR(H42/G42, 0) | J42: =VLOOKUP($B42, 'پایگاه داده حد انتظار'!$A$2:$H$33, 5, FALSE) | K42: =IFERROR(VLOOKUP($B42, 'گزارش عملکرد ماهانه'!$A$2:$F$33, 4, FALSE), 0) | L42: =IFERROR(K42/J42, 0) | M42: =VLOOKUP($B42, 'پایگاه داده حد انتظار'!$A$2:$H$33, 6, FALSE) | N42: =IFERROR(VLOOKUP($B42, 'گزارش عملکرد ماهانه'!$A$2:$F$33, 5, FALSE), 0) | O42: =IFERROR(N42/M42, 0) | P42: =VLOOKUP($B42, 'پایگاه داده حد انتظار'!$A$2:$H$33, 7, FALSE) | Q42: =IFERROR(VLOOKUP($B42, 'گزارش عملکرد ماهانه'!$A$2:$F$33, 6, FALSE), 0) | R42: =IFERROR(Q42/P42, 0) | S42: =VLOOKUP($B42, 'پایگاه داده حد انتظار'!$A$2:$H$33, 8, FALSE) | T42: =ROUND(70 + 30 * (MIN(0.4, 0.1*F42 + 0.3*I42) + MIN(0.5, 0.5*L42 + MAX(0, 0.1*F42 + 0.3*I42 - 0.4)) + MIN(0.1, 0.1*O42)), 1) | U42: =IF(T42>70, RANK(T42, $T$31:$T$62), "-") | V42: =IF(T42<=70, "ضعیف", IF(T42>=90, "عالی", "متوسط")) | W42: =IF((E42+H42+K42+N42+Q42)>0, "ثبت شده", "فاقد گزارش")
... A62: 32 | B62: هرند | C62: =VLOOKUP($B62, 'پایگاه داده حد انتظار'!$A$2:$H$33, 2, FALSE) | D62: =VLOOKUP($B62, 'پایگاه داده حد انتظار'!$A$2:$H$33, 3, FALSE) | E62: =IFERROR(VLOOKUP($B62, 'گزارش عملکرد ماهانه'!$A$2:$F$33, 2, FALSE), 0) | F62: =IFERROR(E62/D62, 0) | G62: =VLOOKUP($B62, 'پایگاه داده حد انتظار'!$A$2:$H$33, 4, FALSE) | H62: =IFERROR(VLOOKUP($B62, 'گزارش عملکرد ماهانه'!$A$2:$F$33, 3, FALSE), 0) | I62: =IFERROR(H62/G62, 0) | J62: =VLOOKUP($B62, 'پایگاه داده حد انتظار'!$A$2:$H$33, 5, FALSE) | K62: =IFERROR(VLOOKUP($B62, 'گزارش عملکرد ماهانه'!$A$2:$F$33, 4, FALSE), 0) | L62: =IFERROR(K62/J62, 0) | M62: =VLOOKUP($B62, 'پایگاه داده حد انتظار'!$A$2:$H$33, 6, FALSE) | N62: =IFERROR(VLOOKUP($B62, 'گزارش عملکرد ماهانه'!$A$2:$F$33, 5, FALSE), 0) | O62: =IFERROR(N62/M62, 0) | P62: =VLOOKUP($B62, 'پایگاه داده حد انتظار'!$A$2:$H$33, 7, FALSE) | Q62: =IFERROR(VLOOKUP($B62, 'گزارش عملکرد ماهانه'!$A$2:$F$33, 6, FALSE), 0) | R62: =IFERROR(Q62/P62, 0) | S62: =VLOOKUP($B62, 'پایگاه داده حد انتظار'!$A$2:$H$33, 8, FALSE) | T62: =ROUND(70 + 30 * (MIN(0.4, 0.1*F62 + 0.3*I62) + MIN(0.5, 0.5*L62 + MAX(0, 0.1*F62 + 0.3*I62 - 0.4)) + MIN(0.1, 0.1*O62)), 1) | U62: =IF(T62>70, RANK(T62, $T$31:$T$62), "-") | V62: =IF(T62<=70, "ضعیف", IF(T62>=90, "عالی", "متوسط")) | W62: =IF((E62+H62+K62+N62+Q62)>0, "ثبت شده", "فاقد گزارش")
A63: - | B63: مجموع کل استان اصفهان | C63: =SUM(C31:C62) | D63: =SUM(D31:D62) | E63: =SUM(E31:E62) | F63: =IFERROR(E63/D63, 0) | G63: =SUM(G31:G62) | H63: =SUM(H31:H62) | I63: =IFERROR(H63/G63, 0) | J63: =SUM(J31:J62) | K63: =SUM(K31:K62) | L63: =IFERROR(K63/J63, 0) | M63: =SUM(M31:M62) | N63: =SUM(N31:N62) | O63: =IFERROR(N63/M63, 0) | P63: =SUM(P31:P62) | Q63: =SUM(Q31:Q62) | R63: =IFERROR(Q63/P63, 0) | S63: =SUM(S31:S62) | T63: =AVERAGE(T31:T62) | U63: - | V63: =IF(T63>=1, "عالی", IF(T63>=0.75, "خوب", IF(T63>=0.5, "متوسط", "نیازمند جهش"))) | W63: =COUNTIF(W31:W62, "ثبت شده") & " از ۳۲ ناحیه"
A64: - | B64: میانگین عملکرد هر ناحیه | C64: =AVERAGE(C31:C62) | D64: =AVERAGE(D31:D62) | E64: =AVERAGE(E31:E62) | F64: =AVERAGE(F31:F62) | G64: =AVERAGE(G31:G62) | H64: =AVERAGE(H31:H62) | I64: =AVERAGE(I31:I62) | J64: =AVERAGE(J31:J62) | ... T64: =AVERAGE(T31:T62) | U64: - | V64: - | W64: -
A65: - | B65: بالاترین رکورد در استان (حداکثر) | C65: =MAX(C31:C62) | D65: =MAX(D31:D62) | E65: =MAX(E31:E62) | F65: =MAX(F31:F62) | G65: =MAX(G31:G62) | H65: =MAX(H31:H62) | I65: =MAX(I31:I62) | J65: =MAX(J31:J62) | ... T65: =MAX(T31:T62) | U65: - | V65: - | W65: -
...

Sheet کارنامه هوشمند
B1: =HYPERLINK("#'داشبورد مانیتورینگ نواحی'!A1", "📊 بازگشت به داشبورد مانیتورینگ جامع نواحی ↗")
B2: انتخاب شهرستان: | C2: آران و بیدگل | D2: 📸 دریافت تصویر کارنامه (PNG)
B3: ماه ارزیابی: | C3: شهریور | D3: سال ارزیابی: | E3: 1405
B4: بخش | C4: حد انتظار | D4: عملکرد واقعی | E4: درصد تحقق
B5: حضوری و توانمندسازی (۳۱×) | C5: =IFERROR(VLOOKUP($C$2, 'پایگاه داده حد انتظار'!$A$2:$H$33, 3, FALSE), 0) | D5: =IFERROR(VLOOKUP($C$2, 'گزارش عملکرد ماهانه'!$A$2:$F$33, 2, FALSE), 0) | E5: =IFERROR(D5/C5, 0)
B6: مجازی/لایو (۲۱۷×) | C6: =IFERROR(VLOOKUP($C$2, 'پایگاه داده حد انتظار'!$A$2:$H$33, 4, FALSE), 0) | D6: =IFERROR(VLOOKUP($C$2, 'گزارش عملکرد ماهانه'!$A$2:$F$33, 3, FALSE), 0) | E6: =IFERROR(D6/C6, 0)
B7: اقدامات خلاقانه (۶۲×) | C7: =IFERROR(VLOOKUP($C$2, 'پایگاه داده حد انتظار'!$A$2:$H$33, 5, FALSE), 0) | D7: =IFERROR(VLOOKUP($C$2, 'گزارش عملکرد ماهانه'!$A$2:$F$33, 4, FALSE), 0) | E7: =IFERROR(D7/C7, 0)
B8: تولیدات رسانه‌ای (۳×) | C8: =IFERROR(VLOOKUP($C$2, 'پایگاه داده حد انتظار'!$A$2:$H$33, 6, FALSE), 0) | D8: =IFERROR(VLOOKUP($C$2, 'گزارش عملکرد ماهانه'!$A$2:$F$33, 5, FALSE), 0) | E8: =IFERROR(D8/C8, 0)
B9: نشست انجمن | C9: =IFERROR(VLOOKUP($C$2, 'پایگاه داده حد انتظار'!$A$2:$H$33, 7, FALSE), 0) | D9: =IFERROR(VLOOKUP($C$2, 'گزارش عملکرد ماهانه'!$A$2:$F$33, 6, FALSE), 0) | E9: =IFERROR(D9/C9, 0)
B11: نمره کل عملکرد (۷۰ تا ۱۰۰): | C11: =ROUND(70 + 30 * (MIN(0.4, 0.1*E5 + 0.3*E6) + MIN(0.5, 0.5*E7 + MAX(0, 0.1*E5 + 0.3*E6 - 0.4)) + MIN(0.1, 0.1*E8)), 1)
B12: رتبه در استان: | C12: =IFERROR(VLOOKUP($C$2, 'داشبورد مانیتورینگ نواحی'!$B$31:$U$62, 20, FALSE), "-")
B13: سطح ارزیابی (۳ سطح): | C13: =IF(C11<=70, "ضعیف", IF(C11>=90, "عالی", "متوسط"))
B14: درصد تحقق وزنی اهداف: | C14: =(MIN(0.4, 0.1*E5 + 0.3*E6) + MIN(0.5, 0.5*E7 + MAX(0, 0.1*E5 + 0.3*E6 - 0.4)) + MIN(0.1, 0.1*E8))
B15: تعداد حوزه مقاومت: | C15: =IFERROR(VLOOKUP(, 'پایگاه داده حد انتظار'!:3, 2, FALSE), 0)
B16: حدانتظار اعضای انجمن: | C16: =IFERROR(VLOOKUP(, 'پایگاه داده حد انتظار'!:3, 8, FALSE), 0)

Sheet گزارش عملکرد ماهانه
A1: نام ناحیه (شهرستان) | B1: حضوری و توانمندسازی (۳۱×) | C1: مجازی/لایو (۲۱۷×) | D1: اقدامات خلاقانه (۶۲×) | E1: تولیدات رسانه‌ای (۳×) | F1: نشست انجمن | G1: دوره ارزیابی: | H1: ='کارنامه هوشمند'!C3 & " " & 'کارنامه هوشمند'!E3
A2: آران و بیدگل | B2: 0 | C2: 0 | D2: 0 | E2: 0 | F2: 0
A3: امام حسین(ع) | B3: 0 | C3: 0 | D3: 0 | E3: 0 | F3: 0
A4: امام رضا(ع) | B4: 0 | C4: 0 | D4: 0 | E4: 0 | F4: 0
A5: امام صادق(ع) | B5: 0 | C5: 0 | D5: 0 | E5: 0 | F5: 0
A6: امام علی(ع) | B6: 0 | C6: 0 | D6: 0 | E6: 0 | F6: 0
A7: اردستان | B7: 0 | C7: 0 | D7: 0 | E7: 0 | F7: 0
A8: برخوار | B8: 46 | C8: 1 | D8: 4396 | E8: 4 | F8: 1
A9: بویین و میاندشت | B9: 0 | C9: 0 | D9: 0 | E9: 0 | F9: 0
A10: تیران و کرون | B10: 0 | C10: 0 | D10: 0 | E10: 0 | F10: 0
A11: جرقویه | B11: 0 | C11: 0 | D11: 0 | E11: 0 | F11: 0
A12: چادگان | B12: 0 | C12: 0 | D12: 0 | E12: 0 | F12: 0
A13: خمینی شهر | B13: 0 | C13: 0 | D13: 0 | E13: 0 | F13: 0
... A33: هرند | B33: 0 | C33: 0 | D33: 0 | E33: 0 | F33: 0

Sheet پایگاه داده حد انتظار
A1: نام ناحیه (شهرستان) | B1: تعداد حوزه | C1: حضوری و توانمندسازی (۳۱×) | D1: مجازی/لایو (۲۱۷×) | E1: اقدامات خلاقانه (۶۲×) | F1: تولیدات رسانه‌ای (۳×) | G1: نشست انجمن | H1: اعضای انجمن
A2: آران و بیدگل | B2: 10 | C2: 310 | D2: 2170 | E2: 620 | F2: 30 | G2: 1 | H2: 22
A3: امام حسین(ع) | B3: 5 | C3: 155 | D3: 1085 | E3: 310 | F3: 15 | G3: 1 | H3: 22
A4: امام رضا(ع) | B4: 22 | C4: 682 | D4: 4774 | E4: 1364 | F4: 66 | G4: 1 | H4: 22
A5: امام صادق(ع) | B5: 22 | C5: 682 | D5: 4774 | E5: 1364 | F5: 66 | G5: 1 | H5: 22
A6: امام علی(ع) | B6: 6 | C6: 186 | D6: 1302 | E6: 372 | F6: 18 | G6: 1 | H6: 22
A7: اردستان | B7: 6 | C7: 186 | D7: 1302 | E7: 372 | F7: 18 | G7: 1 | H7: 22
A8: برخوار | B8: 5 | C8: 155 | D8: 1085 | E8: 310 | F8: 15 | G8: 1 | H8: 22
A9: بویین و میاندشت | B9: 3 | C9: 93 | D9: 651 | E9: 186 | F9: 9 | G9: 1 | H9: 22
A10: تیران و کرون | B10: 6 | C10: 186 | D10: 1302 | E10: 372 | F10: 18 | G10: 1 | H10: 22
A11: جرقویه | B11: 4 | C11: 124 | D11: 868 | E11: 248 | F11: 12 | G11: 1 | H11: 22
A12: چادگان | B12: 5 | C12: 155 | D12: 1085 | E12: 310 | F12: 15 | G12: 1 | H12: 22
A13: خمینی شهر | B13: 9 | C13: 279 | D13: 1953 | E13: 558 | F13: 27 | G13: 1 | H13: 22
... A33: هرند | B33: 4 | C33: 124 | D33: 868 | E33: 248 | F33: 12 | G33: 1 | H33: 22
